Workbook

Sheet START_HERE
A1: Topic | B1: Details
A2: Purpose | B2: Portfolio project for purchasing, procurement, supplier scorecards, inventory and agency buying.
A3: Data status | B3: All operational data is synthetic/simulated and intended for practice, not actual company data.
A4: Time range | B4: Primarily calendar year 2025; monthly records and quarterly scorecards.
A5: Tools | B5: Excel for checks/formulas; SQLite for joins and KPIs; Power BI for dashboards.
A6: Core concepts | B6: PO cycle time, on-time delivery, supplier score, reorder point, stock cover, spend, price variance, open PO exposure, compliance.
A7: Reorder point | B7: Average daily demand × supplier lead time in days + safety stock.
A8: Caution | B8: Synthetic patterns are for learning only; validate definitions before real decisions.
A9: Suggested order | B9: START_HERE → DataDictionary → Products/Suppliers → PurchaseOrders/POLines/POTracking → InventoryMonthly/SalesMonthly → SupplierPerformance → campaign sourcing tables.

Sheet DataDictionary
A1: Table | B1: Key | C1: Definition
A2: Products | B2: ProductID | C2: Unique product key
A3: Suppliers | B3: SupplierID | C3: Unique supplier key
A4: SupplierQuotes | B4: QuoteID | C4: Unique supplier quote key
A5: PurchaseOrders | B5: POID | C5: Unique purchase order key
A6: POLines | B6: POLineID | C6: Unique purchase order line key
A7: POTracking | B7: POID | C7: One logistics tracking record per PO
A8: InventoryMonthly | B8: SnapshotDate + ProductID | C8: Monthly stock and reorder snapshot
A9: SalesMonthly | B9: Month + ProductID | C9: Monthly product sales/usage
A10: SupplierPerformance | B10: SupplierID + Quarter | C10: Quarterly supplier KPI record
A11: Agencies | B11: AgencyID | C11: Creator agency dimension
A12: Campaigns | B12: CampaignID | C12: Campaign budget and spend
... A14: CampaignCompliance | B14: CampaignID | C14: Contract, rights, disclosure and privacy checks

Sheet Products
A1: ProductID | B1: ProductName | C1: Category | D1: UnitCostGBP | E1: AnnualDemandUnits | F1: LeadTimeDaysTarget | G1: SafetyStockUnits | H1: ReorderReviewDays | I1: ReorderPointUnits
A2: P001 | B2: Product 001 | C2: Electronics | D2: 37.46 | E2: 1460 | F2: 14 | G2: 86 | H2: 7 | I2: =ROUNDUP((E2/365)*F2,0)+G2 -> 142
A3: P002 | B3: Product 002 | C3: Home & Kitchen | D3: 57.91 | E3: 6865 | F3: 14 | G3: 89 | H3: 30 | I3: =ROUNDUP((E3/365)*F3,0)+G3 -> 353
A4: P003 | B4: Product 003 | C4: Beauty | D4: 82.69 | E4: 8922 | F4: 28 | G4: 16 | H4: 14 | I4: =ROUNDUP((E4/365)*F4,0)+G4 -> 701
A5: P004 | B5: Product 004 | C5: Office Supplies | D5: 22.54 | E5: 5911 | F5: 21 | G5: 35 | H5: 7 | I5: =ROUNDUP((E5/365)*F5,0)+G5 -> 376
A6: P005 | B6: Product 005 | C6: Sports & Outdoors | D6: 30.99 | E6: 6996 | F6: 21 | G6: 103 | H6: 7 | I6: =ROUNDUP((E6/365)*F6,0)+G6 -> 506
A7: P006 | B7: Product 006 | C7: Electronics | D7: 51.28 | E7: 3158 | F7: 10 | G7: 29 | H7: 14 | I7: =ROUNDUP((E7/365)*F7,0)+G7 -> 116
A8: P007 | B8: Product 007 | C8: Home & Kitchen | D8: 11.34 | E8: 3605 | F8: 14 | G8: 122 | H8: 30 | I8: =ROUNDUP((E8/365)*F8,0)+G8 -> 261
A9: P008 | B9: Product 008 | C9: Beauty | D9: 93.46 | E9: 2128 | F9: 14 | G9: 65 | H9: 30 | I9: =ROUNDUP((E9/365)*F9,0)+G9 -> 147
A10: P009 | B10: Product 009 | C10: Office Supplies | D10: 18.69 | E10: 5993 | F10: 21 | G10: 103 | H10: 14 | I10: =ROUNDUP((E10/365)*F10,0)+G10 -> 448
A11: P010 | B11: Product 010 | C11: Sports & Outdoors | D11: 77.37 | E11: 8113 | F11: 28 | G11: 144 | H11: 30 | I11: =ROUNDUP((E11/365)*F11,0)+G11 -> 767
A12: P011 | B12: Product 011 | C12: Electronics | D12: 65.86 | E12: 1375 | F12: 14 | G12: 95 | H12: 14 | I12: =ROUNDUP((E12/365)*F12,0)+G12 -> 148
A13: P012 | B13: Product 012 | C13: Home & Kitchen | D13: 63.95 | E13: 3673 | F13: 10 | G13: 18 | H13: 14 | I13: =ROUNDUP((E13/365)*F13,0)+G13 -> 119
... A81: P080 | B81: Product 080 | C81: Sports & Outdoors | D81: 72.72 | E81: 3344 | F81: 28 | G81: 83 | H81: 30 | I81: =ROUNDUP((E81/365)*F81,0)+G81 -> 340

Sheet Suppliers
A1: SupplierID | B1: SupplierName | C1: Region | D1: PreferredSupplier | E1: PaymentTermsDays | F1: ContractStatus | G1: RiskTier
A2: S001 | B2: Supplier 01 | C2: UK | D2: Yes | E2: 45 | F2: Expiring Soon | G2: Low
A3: S002 | B3: Supplier 02 | C3: North America | D3: Yes | E3: 45 | F3: Active | G3: Medium
A4: S003 | B4: Supplier 03 | C4: Asia | D4: Yes | E4: 30 | F4: Under Review | G4: Low
A5: S004 | B5: Supplier 04 | C5: EU | D5: Yes | E5: 45 | F5: Under Review | G5: High
A6: S005 | B6: Supplier 05 | C6: North America | D6: Yes | E6: 60 | F6: Active | G6: Medium
A7: S006 | B7: Supplier 06 | C7: EU | D7: Yes | E7: 30 | F7: Under Review | G7: Medium
A8: S007 | B8: Supplier 07 | C8: North America | D8: Yes | E8: 60 | F8: Active | G8: Low
A9: S008 | B9: Supplier 08 | C9: North America | D9: Yes | E9: 60 | F9: Expiring Soon | G9: Medium
A10: S009 | B10: Supplier 09 | C10: EU | D10: No | E10: 60 | F10: Expiring Soon | G10: Low
A11: S010 | B11: Supplier 10 | C11: UK | D11: No | E11: 60 | F11: Active | G11: High
A12: S011 | B12: Supplier 11 | C12: Asia | D12: No | E12: 30 | F12: Active | G12: Medium
A13: S012 | B13: Supplier 12 | C13: Asia | D13: No | E13: 30 | F13: Under Review | G13: Low
... A21: S020 | B21: Supplier 20 | C21: North America | D21: No | E21: 60 | F21: Active | G21: Medium

Sheet SupplierQuotes
A1: QuoteID | B1: ProductID | C1: SupplierID | D1: QuotedUnitPriceGBP | E1: QuotedLeadTimeDays | F1: MOQUnits | G1: QuoteDate | H1: QuoteValidDays
A2: Q0001 | B2: P001 | C2: S020 | D2: 43.3 | E2: 17 | F2: 10 | G2: 45757 | H2: 30
A3: Q0002 | B3: P001 | C3: S009 | D3: 44.39 | E3: 12 | F3: 100 | G3: 45922 | H3: 90
A4: Q0003 | B4: P001 | C4: S002 | D4: 45.1 | E4: 12 | F4: 20 | G4: 45801 | H4: 30
A5: Q0004 | B5: P002 | C5: S008 | D5: 56.74 | E5: 24 | F5: 20 | G5: 45896 | H5: 30
A6: Q0005 | B6: P002 | C6: S001 | D6: 65.54 | E6: 9 | F6: 50 | G6: 45831 | H6: 30
A7: Q0006 | B7: P002 | C7: S017 | D7: 53.99 | E7: 15 | F7: 10 | G7: 45940 | H7: 60
A8: Q0007 | B8: P003 | C8: S009 | D8: 94.06 | E8: 17 | F8: 20 | G8: 45676 | H8: 90
A9: Q0008 | B9: P003 | C9: S015 | D9: 83.58 | E9: 35 | F9: 10 | G9: 45798 | H9: 60
A10: Q0009 | B10: P003 | C10: S016 | D10: 84.63 | E10: 29 | F10: 10 | G10: 45847 | H10: 30
A11: Q0010 | B11: P004 | C11: S011 | D11: 24.41 | E11: 16 | F11: 20 | G11: 45800 | H11: 90
A12: Q0011 | B12: P004 | C12: S009 | D12: 27.46 | E12: 16 | F12: 50 | G12: 45669 | H12: 60
A13: Q0012 | B13: P004 | C13: S002 | D13: 27.09 | E13: 28 | F13: 100 | G13: 45813 | H13: 30
... A241: Q0240 | B241: P080 | C241: S013 | D241: 68.79 | E241: 22 | F241: 50 | G241: 45907 | H241: 30

Sheet PurchaseOrders
A1: POID | B1: SupplierID | C1: OrderDate | D1: RequiredDate | E1: POStatus | F1: Currency | G1: BuyerID | H1: PaymentTermsDays | I1: FollowUpFlag | J1: ActualReceiptDate | K1: DeliveryVarianceDays | L1: DeliveryPerformance | M1: ActualLeadTimeDays
A2: PO0001 | B2: S011 | C2: 45689 | D2: 45722 | E2: Open | F2: GBP | G2: B03 | H2: 45 | I2: =IF(TRIM(E2)="Overdue","Urgent Follow-Up",IF(TRIM(E2)="Received","Complete",IF(OR(TRIM(E2)="Open",TRIM(E2)="Partially Received"),"Monitor","Check Status"))) -> Monitor | J2: =IF(_xlfn.XLOOKUP(A2,POTracking!$A:$A,POTracking!$D:$D,"")=0,"",_xlfn.XLOOKUP(A2,POTracking!$A:$A,POTracking!$D:$D,"")) | K2: =IF(J2="","",J2-D2) | L2: =IF(J2="","Not Yet Received",IF(K2<=0,"On Time/Early","Late")) -> Not Yet Received | M2: =IF(J2="","",J2-C2)
A3: PO0002 | B3: S012 | C3: 45835 | D3: 45857 | E3: Received | F3: GBP | G3: B04 | H3: 30 | I3: =IF(TRIM(E3)="Overdue","Urgent Follow-Up",IF(TRIM(E3)="Received","Complete",IF(OR(TRIM(E3)="Open",TRIM(E3)="Partially Received"),"Monitor","Check Status"))) -> Complete | J3: =IF(_xlfn.XLOOKUP(A3,POTracking!$A:$A,POTracking!$D:$D,"")=0,"",_xlfn.XLOOKUP(A3,POTracking!$A:$A,POTracking!$D:$D,"")) -> 45859 | K3: =IF(J3="","",J3-D3) -> 2 | L3: =IF(J3="","Not Yet Received",IF(K3<=0,"On Time/Early","Late")) -> Late | M3: =IF(J3="","",J3-C3) -> 24
A4: PO0003 | B4: S009 | C4: 45765 | D4: 45781 | E4: Overdue | F4: GBP | G4: B05 | H4: 30 | I4: =IF(TRIM(E4)="Overdue","Urgent Follow-Up",IF(TRIM(E4)="Received","Complete",IF(OR(TRIM(E4)="Open",TRIM(E4)="Partially Received"),"Monitor","Check Status"))) -> Urgent Follow-Up | J4: =IF(_xlfn.XLOOKUP(A4,POTracking!$A:$A,POTracking!$D:$D,"")=0,"",_xlfn.XLOOKUP(A4,POTracking!$A:$A,POTracking!$D:$D,"")) | K4: =IF(J4="","",J4-D4) | L4: =IF(J4="","Not Yet Received",IF(K4<=0,"On Time/Early","Late")) -> Not Yet Received | M4: =IF(J4="","",J4-C4)
A5: PO0004 | B5: S010 | C5: 45808 | D5: 45837 | E5: Received | F5: GBP | G5: B04 | H5: 60 | I5: =IF(TRIM(E5)="Overdue","Urgent Follow-Up",IF(TRIM(E5)="Received","Complete",IF(OR(TRIM(E5)="Open",TRIM(E5)="Partially Received"),"Monitor","Check Status"))) -> Complete | J5: =IF(_xlfn.XLOOKUP(A5,POTracking!$A:$A,POTracking!$D:$D,"")=0,"",_xlfn.XLOOKUP(A5,POTracking!$A:$A,POTracking!$D:$D,"")) -> 45840 | K5: =IF(J5="","",J5-D5) -> 3 | L5: =IF(J5="","Not Yet Received",IF(K5<=0,"On Time/Early","Late")) -> Late | M5: =IF(J5="","",J5-C5) -> 32
A6: PO0005 | B6: S011 | C6: 45747 | D6: 45777 | E6: Received | F6: GBP | G6: B04 | H6: 45 | I6: =IF(TRIM(E6)="Overdue","Urgent Follow-Up",IF(TRIM(E6)="Received","Complete",IF(OR(TRIM(E6)="Open",TRIM(E6)="Partially Received"),"Monitor","Check Status"))) -> Complete | J6: =IF(_xlfn.XLOOKUP(A6,POTracking!$A:$A,POTracking!$D:$D,"")=0,"",_xlfn.XLOOKUP(A6,POTracking!$A:$A,POTracking!$D:$D,"")) -> 45778 | K6: =IF(J6="","",J6-D6) -> 1 | L6: =IF(J6="","Not Yet Received",IF(K6<=0,"On Time/Early","Late")) -> Late | M6: =IF(J6="","",J6-C6) -> 31
A7: PO0006 | B7: S016 | C7: 45883 | D7: 45890 | E7: Received | F7: GBP | G7: B02 | H7: 45 | I7: =IF(TRIM(E7)="Overdue","Urgent Follow-Up",IF(TRIM(E7)="Received","Complete",IF(OR(TRIM(E7)="Open",TRIM(E7)="Partially Received"),"Monitor","Check Status"))) -> Complete | J7: =IF(_xlfn.XLOOKUP(A7,POTracking!$A:$A,POTracking!$D:$D,"")=0,"",_xlfn.XLOOKUP(A7,POTracking!$A:$A,POTracking!$D:$D,"")) -> 45888 | K7: =IF(J7="","",J7-D7) -> -2 | L7: =IF(J7="","Not Yet Received",IF(K7<=0,"On Time/Early","Late")) -> On Time/Early | M7: =IF(J7="","",J7-C7) -> 5
A8: PO0007 | B8: S018 | C8: 45838 | D8: 45851 | E8: Partially Received | F8: GBP | G8: B03 | H8: 30 | I8: =IF(TRIM(E8)="Overdue","Urgent Follow-Up",IF(TRIM(E8)="Received","Complete",IF(OR(TRIM(E8)="Open",TRIM(E8)="Partially Received"),"Monitor","Check Status"))) -> Monitor | J8: =IF(_xlfn.XLOOKUP(A8,POTracking!$A:$A,POTracking!$D:$D,"")=0,"",_xlfn.XLOOKUP(A8,POTracking!$A:$A,POTracking!$D:$D,"")) -> 45856 | K8: =IF(J8="","",J8-D8) -> 5 | L8: =IF(J8="","Not Yet Received",IF(K8<=0,"On Time/Early","Late")) -> Late | M8: =IF(J8="","",J8-C8) -> 18
A9: PO0008 | B9: S001 | C9: 45964 | D9: 45966 | E9: Partially Received | F9: GBP | G9: B02 | H9: 30 | I9: =IF(TRIM(E9)="Overdue","Urgent Follow-Up",IF(TRIM(E9)="Received","Complete",IF(OR(TRIM(E9)="Open",TRIM(E9)="Partially Received"),"Monitor","Check Status"))) -> Monitor | J9: =IF(_xlfn.XLOOKUP(A9,POTracking!$A:$A,POTracking!$D:$D,"")=0,"",_xlfn.XLOOKUP(A9,POTracking!$A:$A,POTracking!$D:$D,"")) -> 45968 | K9: =IF(J9="","",J9-D9) -> 2 | L9: =IF(J9="","Not Yet Received",IF(K9<=0,"On Time/Early","Late")) -> Late | M9: =IF(J9="","",J9-C9) -> 4
A10: PO0009 | B10: S016 | C10: 45718 | D10: 45747 | E10: Received | F10: GBP | G10: B01 | H10: 60 | I10: =IF(TRIM(E10)="Overdue","Urgent Follow-Up",IF(TRIM(E10)="Received","Complete",IF(OR(TRIM(E10)="Open",TRIM(E10)="Partially Received"),"Monitor","Check Status"))) -> Complete | J10: =IF(_xlfn.XLOOKUP(A10,POTracking!$A:$A,POTracking!$D:$D,"")=0,"",_xlfn.XLOOKUP(A10,POTracking!$A:$A,POTracking!$D:$D,"")) -> 45756 | K10: =IF(J10="","",J10-D10) -> 9 | L10: =IF(J10="","Not Yet Received",IF(K10<=0,"On Time/Early","Late")) -> Late | M10: =IF(J10="","",J10-C10) -> 38
A11: PO0010 | B11: S008 | C11: 45827 | D11: 45844 | E11: Received | F11: GBP | G11: B01 | H11: 60 | I11: =IF(TRIM(E11)="Overdue","Urgent Follow-Up",IF(TRIM(E11)="Received","Complete",IF(OR(TRIM(E11)="Open",TRIM(E11)="Partially Received"),"Monitor","Check Status"))) -> Complete | J11: =IF(_xlfn.XLOOKUP(A11,POTracking!$A:$A,POTracking!$D:$D,"")=0,"",_xlfn.XLOOKUP(A11,POTracking!$A:$A,POTracking!$D:$D,"")) -> 45840 | K11: =IF(J11="","",J11-D11) -> -4 | L11: =IF(J11="","Not Yet Received",IF(K11<=0,"On Time/Early","Late")) -> On Time/Early | M11: =IF(J11="","",J11-C11) -> 13
A12: PO0011 | B12: S015 | C12: 45908 | D12: 45934 | E12: Partially Received | F12: GBP | G12: B02 | H12: 45 | I12: =IF(TRIM(E12)="Overdue","Urgent Follow-Up",IF(TRIM(E12)="Received","Complete",IF(OR(TRIM(E12)="Open",TRIM(E12)="Partially Received"),"Monitor","Check Status"))) -> Monitor | J12: =IF(_xlfn.XLOOKUP(A12,POTracking!$A:$A,POTracking!$D:$D,"")=0,"",_xlfn.XLOOKUP(A12,POTracking!$A:$A,POTracking!$D:$D,"")) | K12: =IF(J12="","",J12-D12) | L12: =IF(J12="","Not Yet Received",IF(K12<=0,"On Time/Early","Late")) -> Not Yet Received | M12: =IF(J12="","",J12-C12)
A13: PO0012 | B13: S017 | C13: 45716 | D13: 45743 | E13: Received | F13: GBP | G13: B03 | H13: 60 | I13: =IF(TRIM(E13)="Overdue","Urgent Follow-Up",IF(TRIM(E13)="Received","Complete",IF(OR(TRIM(E13)="Open",TRIM(E13)="Partially Received"),"Monitor","Check Status"))) -> Complete | J13: =IF(_xlfn.XLOOKUP(A13,POTracking!$A:$A,POTracking!$D:$D,"")=0,"",_xlfn.XLOOKUP(A13,POTracking!$A:$A,POTracking!$D:$D,"")) -> 45744 | K13: =IF(J13="","",J13-D13) -> 1 | L13: =IF(J13="","Not Yet Received",IF(K13<=0,"On Time/Early","Late")) -> Late | M13: =IF(J13="","",J13-C13) -> 28
... A321: PO0320 | B321: S005 | C321: 45713 | D321: 45715 | E321: Overdue | F321: GBP | G321: B02 | H321: 30 | I321: =IF(TRIM(E321)="Overdue","Urgent Follow-Up",IF(TRIM(E321)="Received","Complete",IF(OR(TRIM(E321)="Open",TRIM(E321)="Partially Received"),"Monitor","Check Status"))) -> Urgent Follow-Up | J321: =IF(_xlfn.XLOOKUP(A321,POTracking!$A:$A,POTracking!$D:$D,"")=0,"",_xlfn.XLOOKUP(A321,POTracking!$A:$A,POTracking!$D:$D,"")) | K321: =IF(J321="","",J321-D321) | L321: =IF(J321="","Not Yet Received",IF(K321<=0,"On Time/Early","Late")) -> Not Yet Received | M321: =IF(J321="","",J321-C321)

Sheet POSummary
A1: FollowUpFlag | B1: OrderCount
A2: Urgent Follow-Up | B2: =COUNTIF(PurchaseOrders!$I:$I,A2) -> 35
A3: Monitor | B3: =COUNTIF(PurchaseOrders!$I:$I,A3) -> 108
A4: Complete | B4: =COUNTIF(PurchaseOrders!$I:$I,A4) -> 177
A5: Check Status | B5: =COUNTIF(PurchaseOrders!$I:$I,A5) -> 0
A6: Total Orders | B6: =SUM(B2:B5) -> 320

Sheet POLines
A1: POLineID | B1: POID | C1: ProductID | D1: OrderedUnits | E1: UnitPriceGBP | F1: LineValueGBP | G1: ReceivedUnits | H1: SupplierID
A2: POL000101 | B2: PO0001 | C2: P025 | D2: 500 | E2: 59.35 | F2: 29675 | G2: 0 | H2: =_xlfn.XLOOKUP(B2,PurchaseOrders!$A:$A,PurchaseOrders!$B:$B,"Not Found") -> S011 | I2: =SUM(F2:F321) -> 3282463.2
A3: POL000201 | B3: PO0002 | C3: P037 | D3: 500 | E3: 47.39 | F3: 23695 | G3: 500 | H3: =_xlfn.XLOOKUP(B3,PurchaseOrders!$A:$A,PurchaseOrders!$B:$B,"Not Found") -> S012
A4: POL000301 | B4: PO0003 | C4: P004 | D4: 50 | E4: 27.46 | F4: 1373 | G4: 0 | H4: =_xlfn.XLOOKUP(B4,PurchaseOrders!$A:$A,PurchaseOrders!$B:$B,"Not Found") -> S009
A5: POL000401 | B5: PO0004 | C5: P073 | D5: 100 | E5: 57.15 | F5: 5715 | G5: 100 | H5: =_xlfn.XLOOKUP(B5,PurchaseOrders!$A:$A,PurchaseOrders!$B:$B,"Not Found") -> S010
A6: POL000501 | B6: PO0005 | C6: P015 | D6: 200 | E6: 40.64 | F6: 8128 | G6: 200 | H6: =_xlfn.XLOOKUP(B6,PurchaseOrders!$A:$A,PurchaseOrders!$B:$B,"Not Found") -> S011
A7: POL000601 | B7: PO0006 | C7: P066 | D7: 200 | E7: 26.43 | F7: 5286 | G7: 200 | H7: =_xlfn.XLOOKUP(B7,PurchaseOrders!$A:$A,PurchaseOrders!$B:$B,"Not Found") -> S016
A8: POL000701 | B8: PO0007 | C8: P023 | D8: 20 | E8: 7.19 | F8: 143.8 | G8: 6 | H8: =_xlfn.XLOOKUP(B8,PurchaseOrders!$A:$A,PurchaseOrders!$B:$B,"Not Found") -> S018
A9: POL000801 | B9: PO0008 | C9: P061 | D9: 50 | E9: 35.28 | F9: 1764 | G9: 22 | H9: =_xlfn.XLOOKUP(B9,PurchaseOrders!$A:$A,PurchaseOrders!$B:$B,"Not Found") -> S001
A10: POL000901 | B10: PO0009 | C10: P003 | D10: 200 | E10: 84.63 | F10: 16926 | G10: 200 | H10: =_xlfn.XLOOKUP(B10,PurchaseOrders!$A:$A,PurchaseOrders!$B:$B,"Not Found") -> S016
A11: POL001001 | B11: PO0010 | C11: P010 | D11: 150 | E11: 74.98 | F11: 11247 | G11: 150 | H11: =_xlfn.XLOOKUP(B11,PurchaseOrders!$A:$A,PurchaseOrders!$B:$B,"Not Found") -> S008
A12: POL001101 | B12: PO0011 | C12: P038 | D12: 100 | E12: 60.89 | F12: 6089 | G12: 29 | H12: =_xlfn.XLOOKUP(B12,PurchaseOrders!$A:$A,PurchaseOrders!$B:$B,"Not Found") -> S015
A13: POL001201 | B13: PO0012 | C13: P059 | D13: 20 | E13: 32.45 | F13: 649 | G13: 20 | H13: =_xlfn.XLOOKUP(B13,PurchaseOrders!$A:$A,PurchaseOrders!$B:$B,"Not Found") -> S017
A14: POL001301 | B14: PO0013 | C14: P059 | D14: 20 | E14: 32.45 | F14: 649 | G14: 0 | H14: =_xlfn.XLOOKUP(B14,PurchaseOrders!$A:$A,PurchaseOrders!$B:$B,"Not Found") -> S017
... A321: POL032001 | B321: PO0320 | C321: P077 | D321: 50 | E321: 76.26 | F321: 3813 | G321: 0 | H321: =_xlfn.XLOOKUP(B321,PurchaseOrders!$A:$A,PurchaseOrders!$B:$B,"Not Found") -> S005

Sheet POTracking
A1: POID | B1: SupplierConfirmedDate | C1: DispatchDate | D1: ActualReceiptDate | E1: InspectionCompleteDate | F1: DelayReason
A2: PO0001 | B2: 45692 | C2: 45703 | F2: Documentation
A3: PO0002 | B3: 45836 | C3: 45844 | D3: 45859 | E3: 45860 | F3: None
A4: PO0003 | B4: 45768 | C4: 45772 | F4: None
A5: PO0004 | B5: 45808 | C5: 45821 | D5: 45840 | E5: 45841 | F5: None
A6: PO0005 | B6: 45750 | D6: 45778 | E6: 45779 | F6: None
A7: PO0006 | B7: 45885 | D7: 45888 | E7: 45889 | F7: None
A8: PO0007 | B8: 45840 | C8: 45843 | D8: 45856 | E8: 45857 | F8: Transport
A9: PO0008 | B9: 45965 | C9: 45965 | D9: 45968 | E9: 45969 | F9: Transport
A10: PO0009 | B10: 45718 | C10: 45731 | D10: 45756 | E10: 45757 | F10: None
A11: PO0010 | B11: 45830 | C11: 45834 | D11: 45840 | E11: 45841 | F11: None
A12: PO0011 | B12: 45908 | C12: 45919 | F12: Quality Hold
A13: PO0012 | B13: 45717 | D13: 45744 | E13: 45745 | F13: None
A14: PO0013 | B14: 45740 | C14: 45749 | F14: Transport
A15: PO0014 | B15: 46002 | C15: 46016 | F15: Quality Hold
A16: PO0015 | B16: 45703 | D16: 45729 | E16: 45730 | F16: None
A17: PO0016 | B17: 45803 | C17: 45815 | F17: Quality Hold
A18: PO0017 | B18: 45965 | C18: 45972 | D18: 45979 | E18: 45980 | F18: None
A19: PO0018 | B19: 45702 | C19: 45703 | D19: 45707 | E19: 45708 | F19: Documentation
A20: PO0019 | B20: 45850 | C20: 45859 | F20: Capacity
A21: PO0020 | B21: 45719 | C21: 45721 | D21: 45725 | E21: 45726 | F21: None
A22: PO0021 | B22: 45879 | D22: 45894 | E22: 45895 | F22: None
A23: PO0022 | B23: 45879 | C23: 45880 | F23: Documentation
A24: PO0023 | B24: 45857 | C24: 45857 | D24: 45862 | E24: 45863 | F24: None
A25: PO0024 | B25: 45715 | D25: 45713 | E25: 45714 | F25: None
A26: PO0025 | B26: 45745 | C26: 45753 | D26: 45767 | E26: 45768 | F26: None
A27: PO0026 | B27: 45985 | C27: 45984 | F27: Quality Hold
A28: PO0027 | B28: 45857 | C28: 45857 | D28: 45865 | E28: 45866 | F28: None
A29: PO0028 | B29: 45716 | C29: 45720 | D29: 45739 | E29: 45740 | F29: None
A30: PO0029 | B30: 45928 | C30: 45941 | D30: 45954 | E30: 45955 | F30: None
A31: PO0030 | B31: 45871 | D31: 45891 | E31: 45892 | F31: None
A32: PO0031 | B32: 45685 | F32: Capacity
A33: PO0032 | B33: 45696 | C33: 45699 | D33: 45704 | E33: 45705 | F33: Quality Hold
A34: PO0033 | B34: 45864 | C34: 45871 | D34: 45879 | E34: 45880 | F34: None
A35: PO0034 | B35: 45843 | C35: 45843 | D35: 45853 | E35: 45854 | F35: None
A36: PO0035 | B36: 45805 | C36: 45808 | D36: 45818 | E36: 45819 | F36: None
A37: PO0036 | B37: 45777 | C37: 45781 | D37: 45790 | E37: 45791 | F37: None
A38: PO0037 | B38: 45736 | C38: 45744 | F38: Documentation
A39: PO0038 | B39: 45752 | C39: 45765 | D39: 45778 | E39: 45779 | F39: None
A40: PO0039 | B40: 45878 | C40: 45880 | D40: 45887 | E40: 45888 | F40: None
...

Sheet InventoryMonthly
A1: SnapshotDate | B1: ProductID | C1: OnHandUnits | D1: OpenPOUnits | E1: MonthlyDemandUnits | F1: ReorderPointUnits | G1: SafetyStockUnits | H1: ReorderReviewFlag
A2: 45658 | B2: P001 | C2: 365 | D2: 50 | E2: 75 | F2: 142 | G2: 86 | H2: =IF(C2<=_xlfn.XLOOKUP(B2,Products!A:A,Products!I:I),"REORDER REVIEW","Stock OK") -> Stock OK
A3: 45689 | B3: P001 | C3: 375 | D3: 50 | E3: 90 | F3: 142 | G3: 86 | H3: =IF(C3<=_xlfn.XLOOKUP(B3,Products!A:A,Products!I:I),"REORDER REVIEW","Stock OK") -> Stock OK
A4: 45717 | B4: P001 | C4: 443 | D4: 50 | E4: 132 | F4: 142 | G4: 86 | H4: =IF(C4<=_xlfn.XLOOKUP(B4,Products!A:A,Products!I:I),"REORDER REVIEW","Stock OK") -> Stock OK
A5: 45748 | B5: P001 | C5: 565 | D5: 0 | E5: 78 | F5: 142 | G5: 86 | H5: =IF(C5<=_xlfn.XLOOKUP(B5,Products!A:A,Products!I:I),"REORDER REVIEW","Stock OK") -> Stock OK
A6: 45778 | B6: P001 | C6: 536 | D6: 50 | E6: 29 | F6: 142 | G6: 86 | H6: =IF(C6<=_xlfn.XLOOKUP(B6,Products!A:A,Products!I:I),"REORDER REVIEW","Stock OK") -> Stock OK
A7: 45809 | B7: P001 | C7: 525 | D7: 0 | E7: 111 | F7: 142 | G7: 86 | H7: =IF(C7<=_xlfn.XLOOKUP(B7,Products!A:A,Products!I:I),"REORDER REVIEW","Stock OK") -> Stock OK
A8: 45839 | B8: P001 | C8: 364 | D8: 50 | E8: 161 | F8: 142 | G8: 86 | H8: =IF(C8<=_xlfn.XLOOKUP(B8,Products!A:A,Products!I:I),"REORDER REVIEW","Stock OK") -> Stock OK
A9: 45870 | B9: P001 | C9: 371 | D9: 200 | E9: 193 | F9: 142 | G9: 86 | H9: =IF(C9<=_xlfn.XLOOKUP(B9,Products!A:A,Products!I:I),"REORDER REVIEW","Stock OK") -> Stock OK
A10: 45901 | B10: P001 | C10: 447 | D10: 100 | E10: 124 | F10: 142 | G10: 86 | H10: =IF(C10<=_xlfn.XLOOKUP(B10,Products!A:A,Products!I:I),"REORDER REVIEW","Stock OK") -> Stock OK
A11: 45931 | B11: P001 | C11: 629 | D11: 50 | E11: 118 | F11: 142 | G11: 86 | H11: =IF(C11<=_xlfn.XLOOKUP(B11,Products!A:A,Products!I:I),"REORDER REVIEW","Stock OK") -> Stock OK
A12: 45962 | B12: P001 | C12: 498 | D12: 50 | E12: 131 | F12: 142 | G12: 86 | H12: =IF(C12<=_xlfn.XLOOKUP(B12,Products!A:A,Products!I:I),"REORDER REVIEW","Stock OK") -> Stock OK
A13: 45992 | B13: P001 | C13: 714 | D13: 200 | E13: 84 | F13: 142 | G13: 86 | H13: =IF(C13<=_xlfn.XLOOKUP(B13,Products!A:A,Products!I:I),"REORDER REVIEW","Stock OK") -> Stock OK
... A961: 45992 | B961: P080 | C961: 0 | D961: 100 | E961: 233 | F961: 339 | G961: 83 | H961: =IF(C961<=_xlfn.XLOOKUP(B961,Products!A:A,Products!I:I),"REORDER REVIEW","Stock OK") -> REORDER REVIEW

Sheet SalesMonthly
A1: Month | B1: ProductID | C1: UnitsSold | D1: RevenueGBP
A2: 45658 | B2: P001 | C2: 164 | D2: 7742.58
A3: 45689 | B3: P001 | C3: 176 | D3: 12638.63
A4: 45717 | B4: P001 | C4: 112 | D4: 6878.76
A5: 45748 | B5: P001 | C5: 200 | D5: 14767.01
A6: 45778 | B6: P001 | C6: 151 | D6: 9627.31
A7: 45809 | B7: P001 | C7: 109 | D7: 5351.82
A8: 45839 | B8: P001 | C8: 123 | D8: 7754
A9: 45870 | B9: P001 | C9: 122 | D9: 8413.35
A10: 45901 | B10: P001 | C10: 136 | D10: 9579.3
A11: 45931 | B11: P001 | C11: 65 | D11: 3901.89
A12: 45962 | B12: P001 | C12: 172 | D12: 12199.65
A13: 45992 | B13: P001 | C13: 140 | D13: 7459.4
... A961: 45992 | B961: P080 | C961: 413 | D961: 54084.18

Sheet SupplierPerformance
A1: SupplierID | B1: Quarter | C1: OnTimeDeliveryPct | D1: QualityAcceptancePct | E1: PriceVariancePct | F1: ResponsivenessScore | G1: CompliancePct | H1: SupplierScore
A2: S015 | B2: 2025-Q2 | C2: 100 | D2: 100 | E2: 3.4 | F2: 3 | G2: 94.1 | H2: =AVERAGE(C2,D2) -> 100
A3: S009 | B3: 2025-Q4 | C3: 100 | D3: 99.8 | E3: -18 | F3: 3 | G3: 79.3 | H3: =AVERAGE(C3,D3) -> 99.9
A4: S002 | B4: 2025-Q2 | C4: 99.4 | D4: 99.4 | E4: -0.6 | F4: 3 | G4: 98.9 | H4: =AVERAGE(C4,D4) -> 99.4
A5: S013 | B5: 2025-Q4 | C5: 95.1 | D5: 100 | E5: 3.4 | F5: 3 | G5: 84.1 | H5: =AVERAGE(C5,D5) -> 97.55
A6: S012 | B6: 2025-Q4 | C6: 98.8 | D6: 96.1 | E6: 13.3 | F6: 4 | G6: 59.8 | H6: =AVERAGE(C6,D6) -> 97.45
A7: S003 | B7: 2025-Q1 | C7: 94.6 | D7: 100 | E7: 6.9 | F7: 4 | G7: 85.7 | H7: =AVERAGE(C7,D7) -> 97.3
A8: S006 | B8: 2025-Q4 | C8: 100 | D8: 94.4 | E8: 1 | F8: 3 | G8: 71.6 | H8: =AVERAGE(C8,D8) -> 97.2
A9: S014 | B9: 2025-Q3 | C9: 100 | D9: 94.1 | E9: -5.9 | F9: 2 | G9: 88.1 | H9: =AVERAGE(C9,D9) -> 97.05
A10: S008 | B10: 2025-Q3 | C10: 100 | D10: 94 | E10: -2.4 | F10: 3 | G10: 82.1 | H10: =AVERAGE(C10,D10) -> 97
A11: S008 | B11: 2025-Q2 | C11: 100 | D11: 93.1 | E11: 1.9 | F11: 2 | G11: 76.6 | H11: =AVERAGE(C11,D11) -> 96.55
A12: S009 | B12: 2025-Q1 | C12: 93.1 | D12: 100 | E12: -6.3 | F12: 3 | G12: 91.6 | H12: =AVERAGE(C12,D12) -> 96.55
A13: S003 | B13: 2025-Q3 | C13: 100 | D13: 92.9 | E13: 4.3 | F13: 3 | G13: 78.3 | H13: =AVERAGE(C13,D13) -> 96.45
... A81: S010 | B81: 2025-Q4 | C81: 58.3 | D81: 90.8 | E81: -1 | F81: 2 | G81: 95.7 | H81: =AVERAGE(C81,D81) -> 74.55

Sheet SupplierSummary
A1: SupplierID | B1: AverageSupplierScore | C1: PerformanceCategory | D1: SupplierCount | F1: PerformanceCategory | G1: SupplierCount
A2: S003 | B2: =AVERAGEIF(SupplierPerformance!A:A,SupplierPerformance!A7,SupplierPerformance!H:H) -> 94.9 | C2: =IF(B2>=95,"High",IF(B2>=90,"Medium","Low")) -> Medium | F2: High | G2: =COUNTIF(C2:C21,F2) -> 0
A3: S020 | B3: =AVERAGEIF(SupplierPerformance!A:A,SupplierPerformance!A13,SupplierPerformance!H:H) -> 94.9 | C3: =IF(B3>=95,"High",IF(B3>=90,"Medium","Low")) -> Medium | F3: Medium | G3: =COUNTIF(C2:C21,F3) -> 18
A4: S006 | B4: =AVERAGEIF(SupplierPerformance!A:A,SupplierPerformance!A8,SupplierPerformance!H:H) -> 94.8375 | C4: =IF(B4>=95,"High",IF(B4>=90,"Medium","Low")) -> Medium | F4: Low | G4: =COUNTIF(C2:C21,F4) -> 2
A5: S016 | B5: =AVERAGEIF(SupplierPerformance!A:A,SupplierPerformance!A16,SupplierPerformance!H:H) -> 94.8375 | C5: =IF(B5>=95,"High",IF(B5>=90,"Medium","Low")) -> Medium
A6: S001 | B6: =AVERAGEIF(SupplierPerformance!A:A,SupplierPerformance!A18,SupplierPerformance!H:H) -> 94.8375 | C6: =IF(B6>=95,"High",IF(B6>=90,"Medium","Low")) -> Medium
A7: S014 | B7: =AVERAGEIF(SupplierPerformance!A:A,SupplierPerformance!A9,SupplierPerformance!H:H) -> 94.0375 | C7: =IF(B7>=95,"High",IF(B7>=90,"Medium","Low")) -> Medium
A8: S019 | B8: =AVERAGEIF(SupplierPerformance!A:A,SupplierPerformance!A15,SupplierPerformance!H:H) -> 94.0375 | C8: =IF(B8>=95,"High",IF(B8>=90,"Medium","Low")) -> Medium
A9: S008 | B9: =AVERAGEIF(SupplierPerformance!A:A,SupplierPerformance!A10,SupplierPerformance!H:H) -> 93.0875 | C9: =IF(B9>=95,"High",IF(B9>=90,"Medium","Low")) -> Medium
A10: S005 | B10: =AVERAGEIF(SupplierPerformance!A:A,SupplierPerformance!A11,SupplierPerformance!H:H) -> 93.0875 | C10: =IF(B10>=95,"High",IF(B10>=90,"Medium","Low")) -> Medium
A11: S004 | B11: =AVERAGEIF(SupplierPerformance!A:A,SupplierPerformance!A20,SupplierPerformance!H:H) -> 93.0125 | C11: =IF(B11>=95,"High",IF(B11>=90,"Medium","Low")) -> Medium
A12: S012 | B12: =AVERAGEIF(SupplierPerformance!A:A,SupplierPerformance!A6,SupplierPerformance!H:H) -> 92.85 | C12: =IF(B12>=95,"High",IF(B12>=90,"Medium","Low")) -> Medium
A13: S011 | B13: =AVERAGEIF(SupplierPerformance!A:A,SupplierPerformance!A17,SupplierPerformance!H:H) -> 92.65 | C13: =IF(B13>=95,"High",IF(B13>=90,"Medium","Low")) -> Medium
A14: S009 | B14: =AVERAGEIF(SupplierPerformance!A:A,SupplierPerformance!A3,SupplierPerformance!H:H) -> 91.825 | C14: =IF(B14>=95,"High",IF(B14>=90,"Medium","Low")) -> Medium
A15: S017 | B15: =AVERAGEIF(SupplierPerformance!A:A,SupplierPerformance!A12,SupplierPerformance!H:H) -> 91.825 | C15: =IF(B15>=95,"High",IF(B15>=90,"Medium","Low")) -> Medium
A16: S013 | B16: =AVERAGEIF(SupplierPerformance!A:A,SupplierPerformance!A5,SupplierPerformance!H:H) -> 91.3 | C16: =IF(B16>=95,"High",IF(B16>=90,"Medium","Low")) -> Medium
A17: S002 | B17: =AVERAGEIF(SupplierPerformance!A:A,SupplierPerformance!A4,SupplierPerformance!H:H) -> 90.925 | C17: =IF(B17>=95,"High",IF(B17>=90,"Medium","Low")) -> Medium
A18: S007 | B18: =AVERAGEIF(SupplierPerformance!A:A,SupplierPerformance!A14,SupplierPerformance!H:H) -> 90.425 | C18: =IF(B18>=95,"High",IF(B18>=90,"Medium","Low")) -> Medium
A19: S018 | B19: =AVERAGEIF(SupplierPerformance!A:A,SupplierPerformance!A21,SupplierPerformance!H:H) -> 90 | C19: =IF(B19>=95,"High",IF(B19>=90,"Medium","Low")) -> Medium
A20: S015 | B20: =AVERAGEIF(SupplierPerformance!A:A,SupplierPerformance!A2,SupplierPerformance!H:H) -> 89.725 | C20: =IF(B20>=95,"High",IF(B20>=90,"Medium","Low")) -> Low
A21: S010 | B21: =AVERAGEIF(SupplierPerformance!A:A,SupplierPerformance!A19,SupplierPerformance!H:H) -> 86.825 | C21: =IF(B21>=95,"High",IF(B21>=90,"Medium","Low")) -> Low

Sheet DeliverySummary
A1: SupplierID | B1: LateOrderCount | C1: ReceivedOrderCount | D1: AverageLeadTimeDays | E1: OnTimeOrEarlyRate
A2: S016 | B2: =COUNTIFS(PurchaseOrders!$B:$B,A2,PurchaseOrders!$L:$L,"Late") -> 11 | C2: =COUNTIFS(PurchaseOrders!$B:$B,A2,PurchaseOrders!$J:$J,">0") -> 19 | D2: =IFERROR(AVERAGEIFS(PurchaseOrders!$M:$M,PurchaseOrders!$B:$B,A2),"") -> 15.526316 | E2: =IFERROR((C2-B2)/C2,0) -> 0.42105263
A3: S012 | B3: =COUNTIFS(PurchaseOrders!$B:$B,A3,PurchaseOrders!$L:$L,"Late") -> 11 | C3: =COUNTIFS(PurchaseOrders!$B:$B,A3,PurchaseOrders!$J:$J,">0") -> 17 | D3: =IFERROR(AVERAGEIFS(PurchaseOrders!$M:$M,PurchaseOrders!$B:$B,A3),"") -> 14.882353 | E3: =IFERROR((C3-B3)/C3,0) -> 0.35294118
A4: S017 | B4: =COUNTIFS(PurchaseOrders!$B:$B,A4,PurchaseOrders!$L:$L,"Late") -> 10 | C4: =COUNTIFS(PurchaseOrders!$B:$B,A4,PurchaseOrders!$J:$J,">0") -> 13 | D4: =IFERROR(AVERAGEIFS(PurchaseOrders!$M:$M,PurchaseOrders!$B:$B,A4),"") -> 21.538462 | E4: =IFERROR((C4-B4)/C4,0) -> 0.23076923
A5: S002 | B5: =COUNTIFS(PurchaseOrders!$B:$B,A5,PurchaseOrders!$L:$L,"Late") -> 9 | C5: =COUNTIFS(PurchaseOrders!$B:$B,A5,PurchaseOrders!$J:$J,">0") -> 11 | D5: =IFERROR(AVERAGEIFS(PurchaseOrders!$M:$M,PurchaseOrders!$B:$B,A5),"") -> 26.090909 | E5: =IFERROR((C5-B5)/C5,0) -> 0.18181818
A6: S007 | B6: =COUNTIFS(PurchaseOrders!$B:$B,A6,PurchaseOrders!$L:$L,"Late") -> 9 | C6: =COUNTIFS(PurchaseOrders!$B:$B,A6,PurchaseOrders!$J:$J,">0") -> 15 | D6: =IFERROR(AVERAGEIFS(PurchaseOrders!$M:$M,PurchaseOrders!$B:$B,A6),"") -> 16.8 | E6: =IFERROR((C6-B6)/C6,0) -> 0.4
A7: S010 | B7: =COUNTIFS(PurchaseOrders!$B:$B,A7,PurchaseOrders!$L:$L,"Late") -> 9 | C7: =COUNTIFS(PurchaseOrders!$B:$B,A7,PurchaseOrders!$J:$J,">0") -> 16 | D7: =IFERROR(AVERAGEIFS(PurchaseOrders!$M:$M,PurchaseOrders!$B:$B,A7),"") -> 19.3125 | E7: =IFERROR((C7-B7)/C7,0) -> 0.4375
A8: S020 | B8: =COUNTIFS(PurchaseOrders!$B:$B,A8,PurchaseOrders!$L:$L,"Late") -> 8 | C8: =COUNTIFS(PurchaseOrders!$B:$B,A8,PurchaseOrders!$J:$J,">0") -> 19 | D8: =IFERROR(AVERAGEIFS(PurchaseOrders!$M:$M,PurchaseOrders!$B:$B,A8),"") -> 18.789474 | E8: =IFERROR((C8-B8)/C8,0) -> 0.57894737
A9: S005 | B9: =COUNTIFS(PurchaseOrders!$B:$B,A9,PurchaseOrders!$L:$L,"Late") -> 8 | C9: =COUNTIFS(PurchaseOrders!$B:$B,A9,PurchaseOrders!$J:$J,">0") -> 10 | D9: =IFERROR(AVERAGEIFS(PurchaseOrders!$M:$M,PurchaseOrders!$B:$B,A9),"") -> 20 | E9: =IFERROR((C9-B9)/C9,0) -> 0.2
A10: S008 | B10: =COUNTIFS(PurchaseOrders!$B:$B,A10,PurchaseOrders!$L:$L,"Late") -> 7 | C10: =COUNTIFS(PurchaseOrders!$B:$B,A10,PurchaseOrders!$J:$J,">0") -> 12 | D10: =IFERROR(AVERAGEIFS(PurchaseOrders!$M:$M,PurchaseOrders!$B:$B,A10),"") -> 20.166667 | E10: =IFERROR((C10-B10)/C10,0) -> 0.41666667
A11: S009 | B11: =COUNTIFS(PurchaseOrders!$B:$B,A11,PurchaseOrders!$L:$L,"Late") -> 7 | C11: =COUNTIFS(PurchaseOrders!$B:$B,A11,PurchaseOrders!$J:$J,">0") -> 11 | D11: =IFERROR(AVERAGEIFS(PurchaseOrders!$M:$M,PurchaseOrders!$B:$B,A11),"") -> 8.1818182 | E11: =IFERROR((C11-B11)/C11,0) -> 0.36363636
A12: S001 | B12: =COUNTIFS(PurchaseOrders!$B:$B,A12,PurchaseOrders!$L:$L,"Late") -> 5 | C12: =COUNTIFS(PurchaseOrders!$B:$B,A12,PurchaseOrders!$J:$J,">0") -> 16 | D12: =IFERROR(AVERAGEIFS(PurchaseOrders!$M:$M,PurchaseOrders!$B:$B,A12),"") -> 10.0625 | E12: =IFERROR((C12-B12)/C12,0) -> 0.6875
A13: S019 | B13: =COUNTIFS(PurchaseOrders!$B:$B,A13,PurchaseOrders!$L:$L,"Late") -> 5 | C13: =COUNTIFS(PurchaseOrders!$B:$B,A13,PurchaseOrders!$J:$J,">0") -> 12 | D13: =IFERROR(AVERAGEIFS(PurchaseOrders!$M:$M,PurchaseOrders!$B:$B,A13),"") -> 16.416667 | E13: =IFERROR((C13-B13)/C13,0) -> 0.58333333
... A21: S015 | B21: =COUNTIFS(PurchaseOrders!$B:$B,A21,PurchaseOrders!$L:$L,"Late") -> 1 | C21: =COUNTIFS(PurchaseOrders!$B:$B,A21,PurchaseOrders!$J:$J,">0") -> 3 | D21: =IFERROR(AVERAGEIFS(PurchaseOrders!$M:$M,PurchaseOrders!$B:$B,A21),"") -> 16 | E21: =IFERROR((C21-B21)/C21,0) -> 0.66666667

Sheet SupplierSpend
A1: SupplierID | B1: TotalSpendGBP | C1: SpendSharePct
A2: S020 | B2: =SUMIF(POLines!$H:$H,A2,POLines!$F:$F) -> 379504.4 | C2: =IFERROR(B2/SUM($B$2:$B$21),0) -> 0.11561574
A3: S010 | B3: =SUMIF(POLines!$H:$H,A3,POLines!$F:$F) -> 294220.6 | C3: =IFERROR(B3/SUM($B$2:$B$21),0) -> 0.089634089
A4: S011 | B4: =SUMIF(POLines!$H:$H,A4,POLines!$F:$F) -> 273316.2 | C4: =IFERROR(B4/SUM($B$2:$B$21),0) -> 0.083265579
A5: S001 | B5: =SUMIF(POLines!$H:$H,A5,POLines!$F:$F) -> 228020.9 | C5: =IFERROR(B5/SUM($B$2:$B$21),0) -> 0.0694664
A6: S012 | B6: =SUMIF(POLines!$H:$H,A6,POLines!$F:$F) -> 225246.3 | C6: =IFERROR(B6/SUM($B$2:$B$21),0) -> 0.06862112
A7: S016 | B7: =SUMIF(POLines!$H:$H,A7,POLines!$F:$F) -> 214714.8 | C7: =IFERROR(B7/SUM($B$2:$B$21),0) -> 0.065412706
A8: S017 | B8: =SUMIF(POLines!$H:$H,A8,POLines!$F:$F) -> 212611.2 | C8: =IFERROR(B8/SUM($B$2:$B$21),0) -> 0.064771846
A9: S003 | B9: =SUMIF(POLines!$H:$H,A9,POLines!$F:$F) -> 164381.5 | C9: =IFERROR(B9/SUM($B$2:$B$21),0) -> 0.050078703
A10: S007 | B10: =SUMIF(POLines!$H:$H,A10,POLines!$F:$F) -> 163754.8 | C10: =IFERROR(B10/SUM($B$2:$B$21),0) -> 0.049887779
A11: S002 | B11: =SUMIF(POLines!$H:$H,A11,POLines!$F:$F) -> 130902.8 | C11: =IFERROR(B11/SUM($B$2:$B$21),0) -> 0.039879442
A12: S013 | B12: =SUMIF(POLines!$H:$H,A12,POLines!$F:$F) -> 127960.9 | C12: =IFERROR(B12/SUM($B$2:$B$21),0) -> 0.038983194
A13: S009 | B13: =SUMIF(POLines!$H:$H,A13,POLines!$F:$F) -> 121141.2 | C13: =IFERROR(B13/SUM($B$2:$B$21),0) -> 0.036905577
... A21: S006 | B21: =SUMIF(POLines!$H:$H,A21,POLines!$F:$F) -> 41325.5 | C21: =IFERROR(B21/SUM($B$2:$B$21),0) -> 0.012589783
A23: Total Supplier Spend | B23: =SUM(B2:B21) -> 3282463.2

Sheet SupplierFollowUp
A1: SupplierID | B1: UrgentOrderCount | C1: FollowUpPriority
A2: S020 | B2: =COUNTIFS(PurchaseOrders!$B:$B,A2,PurchaseOrders!$I:$I,"Urgent Follow-Up") -> 5 | C2: =IF(B2>=4,"High Priority",IF(B2>=2,"Medium Priority",IF(B2=1,"Low Priority","No Overdue Orders"))) -> High Priority
A3: S009 | B3: =COUNTIFS(PurchaseOrders!$B:$B,A3,PurchaseOrders!$I:$I,"Urgent Follow-Up") -> 4 | C3: =IF(B3>=4,"High Priority",IF(B3>=2,"Medium Priority",IF(B3=1,"Low Priority","No Overdue Orders"))) -> High Priority
A4: S005 | B4: =COUNTIFS(PurchaseOrders!$B:$B,A4,PurchaseOrders!$I:$I,"Urgent Follow-Up") -> 3 | C4: =IF(B4>=4,"High Priority",IF(B4>=2,"Medium Priority",IF(B4=1,"Low Priority","No Overdue Orders"))) -> Medium Priority
A5: S013 | B5: =COUNTIFS(PurchaseOrders!$B:$B,A5,PurchaseOrders!$I:$I,"Urgent Follow-Up") -> 3 | C5: =IF(B5>=4,"High Priority",IF(B5>=2,"Medium Priority",IF(B5=1,"Low Priority","No Overdue Orders"))) -> Medium Priority
A6: S002 | B6: =COUNTIFS(PurchaseOrders!$B:$B,A6,PurchaseOrders!$I:$I,"Urgent Follow-Up") -> 3 | C6: =IF(B6>=4,"High Priority",IF(B6>=2,"Medium Priority",IF(B6=1,"Low Priority","No Overdue Orders"))) -> Medium Priority
A7: S018 | B7: =COUNTIFS(PurchaseOrders!$B:$B,A7,PurchaseOrders!$I:$I,"Urgent Follow-Up") -> 3 | C7: =IF(B7>=4,"High Priority",IF(B7>=2,"Medium Priority",IF(B7=1,"Low Priority","No Overdue Orders"))) -> Medium Priority
A8: S010 | B8: =COUNTIFS(PurchaseOrders!$B:$B,A8,PurchaseOrders!$I:$I,"Urgent Follow-Up") -> 3 | C8: =IF(B8>=4,"High Priority",IF(B8>=2,"Medium Priority",IF(B8=1,"Low Priority","No Overdue Orders"))) -> Medium Priority
A9: S016 | B9: =COUNTIFS(PurchaseOrders!$B:$B,A9,PurchaseOrders!$I:$I,"Urgent Follow-Up") -> 2 | C9: =IF(B9>=4,"High Priority",IF(B9>=2,"Medium Priority",IF(B9=1,"Low Priority","No Overdue Orders"))) -> Medium Priority
A10: S017 | B10: =COUNTIFS(PurchaseOrders!$B:$B,A10,PurchaseOrders!$I:$I,"Urgent Follow-Up") -> 2 | C10: =IF(B10>=4,"High Priority",IF(B10>=2,"Medium Priority",IF(B10=1,"Low Priority","No Overdue Orders"))) -> Medium Priority
A11: S003 | B11: =COUNTIFS(PurchaseOrders!$B:$B,A11,PurchaseOrders!$I:$I,"Urgent Follow-Up") -> 1 | C11: =IF(B11>=4,"High Priority",IF(B11>=2,"Medium Priority",IF(B11=1,"Low Priority","No Overdue Orders"))) -> Low Priority
A12: S008 | B12: =COUNTIFS(PurchaseOrders!$B:$B,A12,PurchaseOrders!$I:$I,"Urgent Follow-Up") -> 1 | C12: =IF(B12>=4,"High Priority",IF(B12>=2,"Medium Priority",IF(B12=1,"Low Priority","No Overdue Orders"))) -> Low Priority
A13: S004 | B13: =COUNTIFS(PurchaseOrders!$B:$B,A13,PurchaseOrders!$I:$I,"Urgent Follow-Up") -> 1 | C13: =IF(B13>=4,"High Priority",IF(B13>=2,"Medium Priority",IF(B13=1,"Low Priority","No Overdue Orders"))) -> Low Priority
... A21: S019 | B21: =COUNTIFS(PurchaseOrders!$B:$B,A21,PurchaseOrders!$I:$I,"Urgent Follow-Up") -> 0 | C21: =IF(B21>=4,"High Priority",IF(B21>=2,"Medium Priority",IF(B21=1,"Low Priority","No Overdue Orders"))) -> No Overdue Orders

Sheet Agencies
A1: AgencyID | B1: AgencyName | C1: Specialism | D1: ContractStatus | E1: PreferredAgency
A2: A001 | B2: Creator Agency 01 | C2: Gaming | D2: Active | E2: Yes
A3: A002 | B3: Creator Agency 02 | C3: Gaming | D3: Under Review | E3: Yes
A4: A003 | B4: Creator Agency 03 | C4: Fitness | D4: Active | E4: Yes
A5: A004 | B5: Creator Agency 04 | C5: Fitness | D5: Under Review | E5: Yes
A6: A005 | B6: Creator Agency 05 | C6: Home | D6: Under Review | E6: Yes
A7: A006 | B7: Creator Agency 06 | C7: Fitness | D7: Expiring Soon | E7: No
A8: A007 | B8: Creator Agency 07 | C8: Beauty | D8: Active | E8: No
A9: A008 | B9: Creator Agency 08 | C9: Lifestyle | D9: Active | E9: No
A10: A009 | B10: Creator Agency 09 | C10: Home | D10: Under Review | E10: No
A11: A010 | B11: Creator Agency 10 | C11: Lifestyle | D11: Active | E11: No
A12: A011 | B12: Creator Agency 11 | C12: Gaming | D12: Active | E12: No
... A16: A015 | B16: Creator Agency 15 | C16: Gaming | D16: Expiring Soon | E16: No

Sheet Campaigns
A1: CampaignID | B1: CampaignName | C1: AgencyID | D1: StartDate | E1: BudgetGBP | F1: ActualSpendGBP | G1: CampaignStatus | H1: PrimaryKPI
A2: C001 | B2: Campaign 001 | C2: A011 | D2: 45867 | E2: 53375.74 | F2: 45349.63 | G2: In Progress | H2: Clicks
A3: C002 | B3: Campaign 002 | C3: A007 | D3: 45864 | E3: 33709.46 | F3: 33298.82 | G3: In Progress | H3: Clicks
A4: C003 | B4: Campaign 003 | C4: A013 | D4: 45810 | E4: 16456.28 | F4: 16423.88 | G4: Planned | H4: Engagement
A5: C004 | B5: Campaign 004 | C5: A008 | D5: 45940 | E5: 77964.25 | F5: 65840.95 | G5: Planned | H5: Conversions
A6: C005 | B6: Campaign 005 | C6: A006 | D6: 45794 | E6: 15863.96 | F6: 14390.41 | G6: Planned | H6: Engagement
A7: C006 | B7: Campaign 006 | C7: A015 | D7: 45959 | E7: 47907.49 | F7: 50216.32 | G7: Completed | H7: Engagement
A8: C007 | B8: Campaign 007 | C8: A014 | D8: 45843 | E8: 23359.21 | F8: 24744.1 | G8: On Hold | H8: Engagement
A9: C008 | B9: Campaign 008 | C9: A006 | D9: 45936 | E9: 61038.06 | F9: 46570.45 | G9: Planned | H9: Conversions
A10: C009 | B10: Campaign 009 | C10: A007 | D10: 45938 | E10: 25512.71 | F10: 24383.55 | G10: Completed | H10: Reach
A11: C010 | B11: Campaign 010 | C11: A011 | D11: 45742 | E11: 70516.97 | F11: 63657.24 | G11: In Progress | H11: Clicks
A12: C011 | B12: Campaign 011 | C12: A012 | D12: 45678 | E12: 49764.26 | F12: 43411.07 | G12: Completed | H12: Engagement
A13: C012 | B13: Campaign 012 | C13: A009 | D13: 45903 | E13: 51734.97 | F13: 42845.22 | G13: Completed | H13: Clicks
... A61: C060 | B61: Campaign 060 | C61: A003 | D61: 45859 | E61: 72664.57 | F61: 63346.46 | G61: In Progress | H61: Engagement

Sheet CreatorPerformance
A1: CampaignID | B1: CreatorCount | C1: Reach | D1: EngagementRatePct | E1: CostPerEngagementGBP | F1: DeliverablesOnTimePct
A2: C001 | B2: 3 | C2: 730958 | D2: 7.05 | E2: 0.87 | F2: 98.3
A3: C002 | B3: 8 | C3: 590569 | D3: 3.29 | E3: 1.18 | F3: 94.4
A4: C003 | B4: 7 | C4: 285591 | D4: 3.01 | E4: 0.78 | F4: 81
A5: C004 | B5: 15 | C5: 538680 | D5: 1.01 | E5: 0.92 | F5: 74.9
A6: C005 | B6: 6 | C6: 903527 | D6: 7.38 | E6: 0.28 | F6: 77.9
A7: C006 | B7: 4 | C7: 836473 | D7: 3.06 | E7: 0.12 | F7: 82.1
A8: C007 | B8: 14 | C8: 317625 | D8: 1.99 | E8: 0.09 | F8: 92.9
A9: C008 | B9: 4 | C9: 66901 | D9: 6.17 | E9: 0.51 | F9: 92.9
A10: C009 | B10: 10 | C10: 164608 | D10: 4.46 | E10: 0.95 | F10: 84
A11: C010 | B11: 4 | C11: 647901 | D11: 1.5 | E11: 1.34 | F11: 66.1
A12: C011 | B12: 10 | C12: 178116 | D12: 6.74 | E12: 1.25 | F12: 67.3
A13: C012 | B13: 15 | C13: 205715 | D13: 4.28 | E13: 0.23 | F13: 87.7
... A61: C060 | B61: 2 | C61: 1092852 | D61: 1.45 | E61: 0.96 | F61: 79.6

Sheet CampaignCompliance
A1: CampaignID | B1: ContractSigned | C1: DisclosureCompliantPct | D1: UsageRightsConfirmed | E1: PrivacyCheckComplete
A2: C001 | B2: No | C2: 78.9 | D2: Yes | E2: Yes
A3: C002 | B3: Yes | C3: 95.2 | D3: No | E3: Yes
A4: C003 | B4: Yes | C4: 90.8 | D4: Yes | E4: Yes
A5: C004 | B5: Yes | C5: 79.8 | D5: Yes | E5: Yes
A6: C005 | B6: Yes | C6: 80.8 | D6: Yes | E6: Yes
A7: C006 | B7: Yes | C7: 77.5 | D7: Yes | E7: Yes
A8: C007 | B8: Yes | C8: 91.3 | D8: Yes | E8: Yes
A9: C008 | B9: Yes | C9: 83.6 | D9: Yes | E9: Yes
A10: C009 | B10: Yes | C10: 91.2 | D10: Yes | E10: Yes
A11: C010 | B11: Yes | C11: 92.8 | D11: Yes | E11: No
A12: C011 | B12: Yes | C12: 79.3 | D12: Yes | E12: Yes
A13: C012 | B13: No | C13: 81.3 | D13: Yes | E13: No
... A61: C060 | B61: Yes | C61: 76.3 | D61: Yes | E61: Yes
